#### - 通过try catch finally来捕获异常
```java
    public static void main(String[] args) {
        int a = 1;
        int b = 0;
        try { //监控区域
            System.out.println(a/b);
        }catch (ArithmeticException e){ //捕获到异常，则执行
            System.out.println("b为0");
        }finally { //无论报不报异常，都执行 。通常用于关闭IO和资源
            System.out.println("计算完成");
        }
    }

```

#### catch中填的是要捕获的异常
比如Throwable是最大的
![image](F3B1AB7DB751492A9C460E113DC2417A)
```java
public class Demo1 {
    public static void main(String[] args) {
        try { //监控区域
            new Demo1().a();
        }catch (Throwable e){ //捕获到异常，则执行
            System.out.println("异常");
        }finally { //无论报不报异常，都执行 。通常用于关闭IO和资源
            System.out.println("计算完成");
        }
    }

    public void a(){b();};
    public void b(){a();};
}
```

#### catch可以给多个异常
```java
public class Demo1 {
    public static void main(String[] args) {
        try { //监控区域
            new Demo1().a();
        }catch (Exception e){ //捕获到异常，则执行
            System.out.println("Exception异常");
        }catch (Throwable e){ //捕获到异常，则执行
            System.out.println("Throwable异常");
        }finally { //无论报不报异常，都执行 。通常用于关闭IO和资源
            System.out.println("计算完成");
        }
    }

    public void a(){b();};
    public void b(){a();};
}
```