#### - 通过throw throws来抛出异常
```java
    public static void main(String[] args) {
        new Demo2().test(1,0);
    }
    //如果方法中无法处理该异常，方法级别可以通过throws抛出异常
    public void test(int a,int b) throws ArithmeticException{
        if(b==0){
            throw new ArithmeticException();//通过throw主动抛出异常
        }
        System.out.println(a/b);
    }
```

抛出了异常的方法，在调用的时候要try catch